Workbook

Sheet README
B2: Continuing Education Program — Operating Budget Model
B3: Fall Term Cycle (22-week period) · Portfolio Sample Workbook
B5: About this workbook
B6: This is an anonymized, rebuilt version of a real operating budget model I developed for a university continuing-education unit. Institution name, staff names, and exact rates have been generalized or adjusted for a public portfolio; the structure, logic, and analytical approach are unchanged from the live version used for planning.
B8: What it does
B9: - Models personnel, platform, communications, presenter honoraria, and student-assessor cost categories for a 22-week program cycle.
B10: - Separates confirmed costs from enrollment-dependent and proposal-dependent costs (clearly flagged).
B11: - Adds a revenue layer (live session + course pricing) to calculate net position / break-even, which the original budget did not include.
B12: - Runs a sensitivity analysis across the variables with the most planning uncertainty: enrollment volume, assessor hours per participant, personnel rate changes, and pricing tiers.
B13: - Includes a one-variable impact ranking (tornado-style) so a reader can see at a glance which assumption moves the budget the most.
B15: How to use it
B16: 1. Start on the Assumptions tab - every blue cell is a live input. Change any of them, and the rest of the workbook recalculates.
... B24: Tabs: README → Assumptions → Budget Model → Sensitivity Analysis → Dashboard

Sheet Assumptions
B2: Model Assumptions
B3: All blue cells are editable inputs. Everything downstream recalculates from this tab.
B5: 1. Program Period
B6: Program length | C6: 22 | D6: weeks | F6: Aug 1 – Dec 31 (Fall term cycle)
B8: 2. Personnel Rates & Hours
B9: Program Supervisor — hrs/week | C9: 17 | D9: hrs/wk
B10: Program Supervisor — hourly rate | C10: 40 | D10: $/hr
B11: Instructional Technologist — hrs/week | C11: 35 | D11: hrs/wk
B12: Instructional Technologist — hourly rate | C12: 30 | D12: $/hr
B13: Personnel rate adjustment (scenario lever) | C13: 0 | D13: % | F13: Applied to both roles in sensitivity test
B15: 3. Platform & Hosting
B16: Platform subscription — monthly | C16: 200 | D16: $/mo | F16: Modeled at full retail; no prior subscription assumed
B17: Platform subscription — months billed | C17: 5 | D17: months
B18: Site hosting — flat rate | C18: 200 | D18: $ | F18: One-time, full period
B20: 4. Communications & Outreach
B21: Sessions requiring design/comms support | C21: 5 | D21: sessions | F21: Webinars + workshops in the term
B22: Design & promo cost per session | C22: 60 | D22: $/session | F22: Graphics, certificates, social assets
B23: Email/distribution platform — monthly | C23: 0 | D23: $/mo | F23: 0 if covered by institutional license
B25: 5. Presenter & Facilitator Honoraria
B26: Webinars planned (term) | C26: 3 | D26: sessions
B27: Honorarium per webinar presenter | C27: 150 | D27: $
B28: Workshops planned (term) | C28: 1 | D28: sessions
B29: Honorarium per workshop facilitator | C29: 300 | D29: $
B31: 6. Student Assessor Honoraria (evergreen courses)
B32: Graduate assessor rate | C32: 24 | D32: $/hr
B33: Undergraduate assessor rate | C33: 20 | D33: $/hr
B34: Assessor hours per review batch | C34: 1.5 | D34: hrs/batch | F34: Corrected: one review hour covers a BATCH of participants (batch-graded single assessed piece), not one hour per individual participant.
B35: Share of assessment load — graduate | C35: 0.7 | D35: % | F35: Remainder assumed undergraduate
B37: 7. Enrollment & Registration (base case)
B38: Avg. registrations per webinar | C38: 12 | D38: people
B39: Avg. registrations per workshop | C39: 15 | D39: people
B40: Evergreen course enrollment (Nov–Dec intake) | C40: 40 | D40: people | F40: Drives assessor honoraria
B42: 8. Pricing (for revenue / net position view)
B43: Live webinar price | C43: 45 | D43: $
B44: Live workshop price | C44: 85 | D44: $
B45: Evergreen course price | C45: 150 | D45: $
B47: 9. Assessor Review Batching (correction)
B48: Participants per assessor review batch | C48: 10 | D48: ppl/batch | F48: One hour of assessor time reviews this many participants' submissions (batch-level check, not per-person deep marking).
B50: 10. ROI Scenario Parameters — Open Call Outcomes
B51: Evergreen courses in scenario (both cases) | C51: 2 | D51: courses | F51: Fixed per Fall 2026 plan — same in Low and High Open Call cases
...

Sheet Budget Model
B2: Operating Budget — Base Case
B3: Fall term cycle · all costs in CAD · formulas link live to the Assumptions tab
B5: Line Item | C5: Rate | D5: Hours / Units | E5: Total (CAD) | G5: Notes
B6: 1. Personnel — Program Supervisor & Instructional Technologist
B7: Program Supervisor | C7: =Assumptions!$C$10*(1+Assumptions!$C$13) -> 40 | D7: =Assumptions!$C$9*Assumptions!$C$6 -> 374 | E7: =C7*D7 -> 14960 | G7: Rate includes sensitivity adjustment lever
B8: Instructional Technologist | C8: =Assumptions!$C$12*(1+Assumptions!$C$13) -> 30 | D8: =Assumptions!$C$11*Assumptions!$C$6 -> 770 | E8: =C8*D8 -> 23100 | G8: Rate includes sensitivity adjustment lever
B9: Personnel Subtotal | E9: =SUM(E7:E8) -> 38060
B11: 2. Digital Learning Platform & Hosting
B12: Platform subscription | C12: =Assumptions!$C$16 -> 200 | D12: =Assumptions!$C$17 -> 5 | E12: =C12*D12 -> 1000 | G12: Modeled at full retail (no prior subscription assumed)
B13: Site hosting | C13: =Assumptions!$C$18 -> 200 | D13: 1 | E13: =C13*D13 -> 200 | G13: Flat rate, full period
B14: Platform Subtotal | E14: =SUM(E12:E13) -> 1200
B16: 3. Communications & Outreach
B17: Design & promo materials | C17: =Assumptions!$C$22 -> 60 | D17: =Assumptions!$C$21 -> 5 | E17: =C17*D17 -> 300 | G17: Per-session graphics, certificates, social assets
B18: Email / distribution platform | C18: =Assumptions!$C$23 -> 0 | D18: =Assumptions!$C$6/4.33 -> 5.0808314 | E18: =C18*D18 -> 0 | G18: Set to $0 if covered by institutional license
B19: Communications Subtotal | E19: =SUM(E17:E18) -> 300
B21: 4. Presenter & Facilitator Honoraria (Open Call for Proposals)
B22: Webinar presenters | C22: =Assumptions!$C$27 -> 150 | D22: =Assumptions!$C$26 -> 3 | E22: =C22*D22 -> 450 | G22: Estimate — confirmed only once proposals are reviewed
B23: Workshop facilitators | C23: =Assumptions!$C$29 -> 300 | D23: =Assumptions!$C$28 -> 1 | E23: =C23*D23 -> 300 | G23: Estimate — confirmed only once proposals are reviewed
B24: Presenter Honoraria Subtotal (Estimate) | E24: =SUM(E22:E23) -> 750
B26: 5. Student Assessor Honoraria — Evergreen Courses (Est. Nov 2026 intake)
B27: Graduate assessor hours | C27: =Assumptions!$C$32 -> 24 | D27: =ROUNDUP((Assumptions!$C$40)/Assumptions!$C$48,0)*Assumptions!$C$34*Assumptions!$C$35 -> 4.2 | E27: =C27*D27 -> 100.8 | G27: Hours scale in batches of 10 participants, not 1:1 per person
B28: Undergraduate assessor hours | C28: =Assumptions!$C$33 -> 20 | D28: =ROUNDUP((Assumptions!$C$40)/Assumptions!$C$48,0)*Assumptions!$C$34*(1-Assumptions!$C$35) -> 1.8 | E28: =C28*D28 -> 36 | G28: Hours scale in batches of 10 participants, not 1:1 per person
B29: Assessor Honoraria Subtotal (Estimate) | E29: =SUM(E27:E28) -> 136.8
B32: TOTAL CONFIRMED COSTS (Personnel + Platform) | E32: =E9+E14 -> 39260
B33: TOTAL BUDGET (incl. communications, honoraria & assessor estimates) | E33: =E9+E14+E19+E24+E29 -> 40446.8
B35: 6. Revenue & Net Position (added view — not in original budget)
B36: Webinar registration revenue | C36: =Assumptions!$C$43 -> 45 | D36: =Assumptions!$C$38*Assumptions!$C$26 -> 36 | E36: =C36*D36 -> 1620 | G36: Registrations × sessions
B37: Workshop registration revenue | C37: =Assumptions!$C$44 -> 85 | D37: =Assumptions!$C$39*Assumptions!$C$28 -> 15 | E37: =C37*D37 -> 1275 | G37: Registrations × sessions
B38: Evergreen course revenue | C38: =Assumptions!$C$45 -> 150 | D38: =Assumptions!$C$40 -> 40 | E38: =C38*D38 -> 6000 | G38: Nov–Dec intake
B39: Revenue Subtotal | E39: =SUM(E36:E38) -> 8895
B41: NET POSITION (Revenue − Total Budget) | E41: =E39-E33 -> -31551.8

Sheet Sensitivity Analysis
B2: Sensitivity Analysis
B3: Stress-testing the budget against the assumptions with the most planning uncertainty
B5: 1. Assessor Honoraria Cost — Enrollment × Hours-per-Participant
B6: The assessor line is the most enrollment-sensitive cost in the model (it only activates once the Nov intake opens, and scales directly with sign-ups). This grid recomputes total assessor cost for each combination, independent of the live Assumptions tab inputs.
B7: Enrollment \ Hrs/batch (batch = 10 ppl) | C7: 1 | D7: 1.5 | E7: 2 | F7: 2.5
B8: 20 | C8: =(ROUNDUP((20)/Assumptions!$C$48,0)*1*Assumptions!$C$35)*Assumptions!$C$32+(ROUNDUP((20)/Assumptions!$C$48,0)*1*(1-Assumptions!$C$35))*Assumptions!$C$33 -> 45.6 | D8: =(ROUNDUP((20)/Assumptions!$C$48,0)*1.5*Assumptions!$C$35)*Assumptions!$C$32+(ROUNDUP((20)/Assumptions!$C$48,0)*1.5*(1-Assumptions!$C$35))*Assumptions!$C$33 -> 68.4 | E8: =(ROUNDUP((20)/Assumptions!$C$48,0)*2*Assumptions!$C$35)*Assumptions!$C$32+(ROUNDUP((20)/Assumptions!$C$48,0)*2*(1-Assumptions!$C$35))*Assumptions!$C$33 -> 91.2 | F8: =(ROUNDUP((20)/Assumptions!$C$48,0)*2.5*Assumptions!$C$35)*Assumptions!$C$32+(ROUNDUP((20)/Assumptions!$C$48,0)*2.5*(1-Assumptions!$C$35))*Assumptions!$C$33 -> 114
B9: 40 | C9: =(ROUNDUP((40)/Assumptions!$C$48,0)*1*Assumptions!$C$35)*Assumptions!$C$32+(ROUNDUP((40)/Assumptions!$C$48,0)*1*(1-Assumptions!$C$35))*Assumptions!$C$33 -> 91.2 | D9: =(ROUNDUP((40)/Assumptions!$C$48,0)*1.5*Assumptions!$C$35)*Assumptions!$C$32+(ROUNDUP((40)/Assumptions!$C$48,0)*1.5*(1-Assumptions!$C$35))*Assumptions!$C$33 -> 136.8 | E9: =(ROUNDUP((40)/Assumptions!$C$48,0)*2*Assumptions!$C$35)*Assumptions!$C$32+(ROUNDUP((40)/Assumptions!$C$48,0)*2*(1-Assumptions!$C$35))*Assumptions!$C$33 -> 182.4 | F9: =(ROUNDUP((40)/Assumptions!$C$48,0)*2.5*Assumptions!$C$35)*Assumptions!$C$32+(ROUNDUP((40)/Assumptions!$C$48,0)*2.5*(1-Assumptions!$C$35))*Assumptions!$C$33 -> 228
B10: 60 | C10: =(ROUNDUP((60)/Assumptions!$C$48,0)*1*Assumptions!$C$35)*Assumptions!$C$32+(ROUNDUP((60)/Assumptions!$C$48,0)*1*(1-Assumptions!$C$35))*Assumptions!$C$33 -> 136.8 | D10: =(ROUNDUP((60)/Assumptions!$C$48,0)*1.5*Assumptions!$C$35)*Assumptions!$C$32+(ROUNDUP((60)/Assumptions!$C$48,0)*1.5*(1-Assumptions!$C$35))*Assumptions!$C$33 -> 205.2 | E10: =(ROUNDUP((60)/Assumptions!$C$48,0)*2*Assumptions!$C$35)*Assumptions!$C$32+(ROUNDUP((60)/Assumptions!$C$48,0)*2*(1-Assumptions!$C$35))*Assumptions!$C$33 -> 273.6 | F10: =(ROUNDUP((60)/Assumptions!$C$48,0)*2.5*Assumptions!$C$35)*Assumptions!$C$32+(ROUNDUP((60)/Assumptions!$C$48,0)*2.5*(1-Assumptions!$C$35))*Assumptions!$C$33 -> 342
B11: 80 | C11: =(ROUNDUP((80)/Assumptions!$C$48,0)*1*Assumptions!$C$35)*Assumptions!$C$32+(ROUNDUP((80)/Assumptions!$C$48,0)*1*(1-Assumptions!$C$35))*Assumptions!$C$33 -> 182.4 | D11: =(ROUNDUP((80)/Assumptions!$C$48,0)*1.5*Assumptions!$C$35)*Assumptions!$C$32+(ROUNDUP((80)/Assumptions!$C$48,0)*1.5*(1-Assumptions!$C$35))*Assumptions!$C$33 -> 273.6 | E11: =(ROUNDUP((80)/Assumptions!$C$48,0)*2*Assumptions!$C$35)*Assumptions!$C$32+(ROUNDUP((80)/Assumptions!$C$48,0)*2*(1-Assumptions!$C$35))*Assumptions!$C$33 -> 364.8 | F11: =(ROUNDUP((80)/Assumptions!$C$48,0)*2.5*Assumptions!$C$35)*Assumptions!$C$32+(ROUNDUP((80)/Assumptions!$C$48,0)*2.5*(1-Assumptions!$C$35))*Assumptions!$C$33 -> 456
B12: 100 | C12: =(ROUNDUP((100)/Assumptions!$C$48,0)*1*Assumptions!$C$35)*Assumptions!$C$32+(ROUNDUP((100)/Assumptions!$C$48,0)*1*(1-Assumptions!$C$35))*Assumptions!$C$33 -> 228 | D12: =(ROUNDUP((100)/Assumptions!$C$48,0)*1.5*Assumptions!$C$35)*Assumptions!$C$32+(ROUNDUP((100)/Assumptions!$C$48,0)*1.5*(1-Assumptions!$C$35))*Assumptions!$C$33 -> 342 | E12: =(ROUNDUP((100)/Assumptions!$C$48,0)*2*Assumptions!$C$35)*Assumptions!$C$32+(ROUNDUP((100)/Assumptions!$C$48,0)*2*(1-Assumptions!$C$35))*Assumptions!$C$33 -> 456 | F12: =(ROUNDUP((100)/Assumptions!$C$48,0)*2.5*Assumptions!$C$35)*Assumptions!$C$32+(ROUNDUP((100)/Assumptions!$C$48,0)*2.5*(1-Assumptions!$C$35))*Assumptions!$C$33 -> 570
B13: Base case ≈ 40 people ÷ 10 = 4 batches × 1.5 hrs (highlighted column/row above)
B15: 2. Personnel Rate Sensitivity — Total Budget Impact
B16: Personnel is the single largest cost category (roughly 90%+ of confirmed costs), so even a small rate change moves the whole budget. This recomputes Total Budget directly using the same logic as the Budget Model tab, varying only the personnel rate adjustment.
B17: Rate Adjustment | C17: Program Supervisor | D17: Instr. Technologist | E17: Personnel Subtotal | F17: Total Budget (all categories) | G17: Δ vs. Base Case
B18: -0.1 | C18: =(Assumptions!$C$10*(1+-0.1))*(Assumptions!$C$9*Assumptions!$C$6) -> 13464 | D18: =(Assumptions!$C$12*(1+-0.1))*(Assumptions!$C$11*Assumptions!$C$6) -> 20790 | E18: =C18+D18 -> 34254 | F18: =E18+'Budget Model'!$E$14+'Budget Model'!$E$19+'Budget Model'!$E$24+'Budget Model'!$E$29 -> 36640.8 | G18: =F18-$F$20 -> -3806
B19: -0.05 | C19: =(Assumptions!$C$10*(1+-0.05))*(Assumptions!$C$9*Assumptions!$C$6) -> 14212 | D19: =(Assumptions!$C$12*(1+-0.05))*(Assumptions!$C$11*Assumptions!$C$6) -> 21945 | E19: =C19+D19 -> 36157 | F19: =E19+'Budget Model'!$E$14+'Budget Model'!$E$19+'Budget Model'!$E$24+'Budget Model'!$E$29 -> 38543.8 | G19: =F19-$F$20 -> -1903
B20: 0 | C20: =(Assumptions!$C$10*(1+0))*(Assumptions!$C$9*Assumptions!$C$6) -> 14960 | D20: =(Assumptions!$C$12*(1+0))*(Assumptions!$C$11*Assumptions!$C$6) -> 23100 | E20: =C20+D20 -> 38060 | F20: =E20+'Budget Model'!$E$14+'Budget Model'!$E$19+'Budget Model'!$E$24+'Budget Model'!$E$29 -> 40446.8 | G20: =F20-$F$20 -> 0
B21: 0.05 | C21: =(Assumptions!$C$10*(1+0.05))*(Assumptions!$C$9*Assumptions!$C$6) -> 15708 | D21: =(Assumptions!$C$12*(1+0.05))*(Assumptions!$C$11*Assumptions!$C$6) -> 24255 | E21: =C21+D21 -> 39963 | F21: =E21+'Budget Model'!$E$14+'Budget Model'!$E$19+'Budget Model'!$E$24+'Budget Model'!$E$29 -> 42349.8 | G21: =F21-$F$20 -> 1903
B22: 0.1 | C22: =(Assumptions!$C$10*(1+0.1))*(Assumptions!$C$9*Assumptions!$C$6) -> 16456 | D22: =(Assumptions!$C$12*(1+0.1))*(Assumptions!$C$11*Assumptions!$C$6) -> 25410 | E22: =C22+D22 -> 41866 | F22: =E22+'Budget Model'!$E$14+'Budget Model'!$E$19+'Budget Model'!$E$24+'Budget Model'!$E$29 -> 44252.8 | G22: =F22-$F$20 -> 3806
B24: Highlighted row = base case (0% adjustment), matches Budget Model total
B26: 3. Net Position — Enrollment Scenario × Pricing Tier
B27: Combines the revenue side with the full cost build to test break-even risk: how participation levels and pricing strategy together determine whether the term cycle is net-positive or net-negative, holding all confirmed costs constant.
B28: Enrollment scenario \ Pricing | C28: Conservative (-15%) | D28: Current | E28: Premium (+15%)
B29: Low | C29: =((Assumptions!$C$43*0.85)*(Assumptions!$C$38*0.5)*Assumptions!$C$26+(Assumptions!$C$44*0.85)*(Assumptions!$C$39*0.5)*Assumptions!$C$28+(Assumptions!$C$45*0.85)*(Assumptions!$C$40*0.5))-('Budget Model'!$E$9+'Budget Model'!$E$14+'Budget Model'!$E$19+'Budget Model'!$E$24+(ROUNDUP(((Assumptions!$C$40*0.5))/Assumptions!$C$48,0)*Assumptions!$C$34*Assumptions!$C$35)*Assumptions!$C$32+(ROUNDUP(((Assumptions!$C$40*0.5))/Assumptions!$C$48,0)*Assumptions!$C$34*(1-Assumptions!$C$35))*Assumptions!$C$33) -> -36598.025 | D29: =((Assumptions!$C$43*1)*(Assumptions!$C$38*0.5)*Assumptions!$C$26+(Assumptions!$C$44*1)*(Assumptions!$C$39*0.5)*Assumptions!$C$28+(Assumptions!$C$45*1)*(Assumptions!$C$40*0.5))-('Budget Model'!$E$9+'Budget Model'!$E$14+'Budget Model'!$E$19+'Budget Model'!$E$24+(ROUNDUP(((Assumptions!$C$40*0.5))/Assumptions!$C$48,0)*Assumptions!$C$34*Assumptions!$C$35)*Assumptions!$C$32+(ROUNDUP(((Assumptions!$C$40*0.5))/Assumptions!$C$48,0)*Assumptions!$C$34*(1-Assumptions!$C$35))*Assumptions!$C$33) -> -35930.9 | E29: =((Assumptions!$C$43*1.15)*(Assumptions!$C$38*0.5)*Assumptions!$C$26+(Assumptions!$C$44*1.15)*(Assumptions!$C$39*0.5)*Assumptions!$C$28+(Assumptions!$C$45*1.15)*(Assumptions!$C$40*0.5))-('Budget Model'!$E$9+'Budget Model'!$E$14+'Budget Model'!$E$19+'Budget Model'!$E$24+(ROUNDUP(((Assumptions!$C$40*0.5))/Assumptions!$C$48,0)*Assumptions!$C$34*Assumptions!$C$35)*Assumptions!$C$32+(ROUNDUP(((Assumptions!$C$40*0.5))/Assumptions!$C$48,0)*Assumptions!$C$34*(1-Assumptions!$C$35))*Assumptions!$C$33) -> -35263.775
B30: Base | C30: =((Assumptions!$C$43*0.85)*(Assumptions!$C$38*1)*Assumptions!$C$26+(Assumptions!$C$44*0.85)*(Assumptions!$C$39*1)*Assumptions!$C$28+(Assumptions!$C$45*0.85)*(Assumptions!$C$40*1))-('Budget Model'!$E$9+'Budget Model'!$E$14+'Budget Model'!$E$19+'Budget Model'!$E$24+(ROUNDUP(((Assumptions!$C$40*1))/Assumptions!$C$48,0)*Assumptions!$C$34*Assumptions!$C$35)*Assumptions!$C$32+(ROUNDUP(((Assumptions!$C$40*1))/Assumptions!$C$48,0)*Assumptions!$C$34*(1-Assumptions!$C$35))*Assumptions!$C$33) -> -32886.05 | D30: =((Assumptions!$C$43*1)*(Assumptions!$C$38*1)*Assumptions!$C$26+(Assumptions!$C$44*1)*(Assumptions!$C$39*1)*Assumptions!$C$28+(Assumptions!$C$45*1)*(Assumptions!$C$40*1))-('Budget Model'!$E$9+'Budget Model'!$E$14+'Budget Model'!$E$19+'Budget Model'!$E$24+(ROUNDUP(((Assumptions!$C$40*1))/Assumptions!$C$48,0)*Assumptions!$C$34*Assumptions!$C$35)*Assumptions!$C$32+(ROUNDUP(((Assumptions!$C$40*1))/Assumptions!$C$48,0)*Assumptions!$C$34*(1-Assumptions!$C$35))*Assumptions!$C$33) -> -31551.8 | E30: =((Assumptions!$C$43*1.15)*(Assumptions!$C$38*1)*Assumptions!$C$26+(Assumptions!$C$44*1.15)*(Assumptions!$C$39*1)*Assumptions!$C$28+(Assumptions!$C$45*1.15)*(Assumptions!$C$40*1))-('Budget Model'!$E$9+'Budget Model'!$E$14+'Budget Model'!$E$19+'Budget Model'!$E$24+(ROUNDUP(((Assumptions!$C$40*1))/Assumptions!$C$48,0)*Assumptions!$C$34*Assumptions!$C$35)*Assumptions!$C$32+(ROUNDUP(((Assumptions!$C$40*1))/Assumptions!$C$48,0)*Assumptions!$C$34*(1-Assumptions!$C$35))*Assumptions!$C$33) -> -30217.55
B31: High | C31: =((Assumptions!$C$43*0.85)*(Assumptions!$C$38*1.5)*Assumptions!$C$26+(Assumptions!$C$44*0.85)*(Assumptions!$C$39*1.5)*Assumptions!$C$28+(Assumptions!$C$45*0.85)*(Assumptions!$C$40*1.5))-('Budget Model'!$E$9+'Budget Model'!$E$14+'Budget Model'!$E$19+'Budget Model'!$E$24+(ROUNDUP(((Assumptions!$C$40*1.5))/Assumptions!$C$48,0)*Assumptions!$C$34*Assumptions!$C$35)*Assumptions!$C$32+(ROUNDUP(((Assumptions!$C$40*1.5))/Assumptions!$C$48,0)*Assumptions!$C$34*(1-Assumptions!$C$35))*Assumptions!$C$33) -> -29174.075 | D31: =((Assumptions!$C$43*1)*(Assumptions!$C$38*1.5)*Assumptions!$C$26+(Assumptions!$C$44*1)*(Assumptions!$C$39*1.5)*Assumptions!$C$28+(Assumptions!$C$45*1)*(Assumptions!$C$40*1.5))-('Budget Model'!$E$9+'Budget Model'!$E$14+'Budget Model'!$E$19+'Budget Model'!$E$24+(ROUNDUP(((Assumptions!$C$40*1.5))/Assumptions!$C$48,0)*Assumptions!$C$34*Assumptions!$C$35)*Assumptions!$C$32+(ROUNDUP(((Assumptions!$C$40*1.5))/Assumptions!$C$48,0)*Assumptions!$C$34*(1-Assumptions!$C$35))*Assumptions!$C$33) -> -27172.7 | E31: =((Assumptions!$C$43*1.15)*(Assumptions!$C$38*1.5)*Assumptions!$C$26+(Assumptions!$C$44*1.15)*(Assumptions!$C$39*1.5)*Assumptions!$C$28+(Assumptions!$C$45*1.15)*(Assumptions!$C$40*1.5))-('Budget Model'!$E$9+'Budget Model'!$E$14+'Budget Model'!$E$19+'Budget Model'!$E$24+(ROUNDUP(((Assumptions!$C$40*1.5))/Assumptions!$C$48,0)*Assumptions!$C$34*Assumptions!$C$35)*Assumptions!$C$32+(ROUNDUP(((Assumptions!$C$40*1.5))/Assumptions!$C$48,0)*Assumptions!$C$34*(1-Assumptions!$C$35))*Assumptions!$C$33) -> -25171.325
B33: Green = net-positive term; red = the program runs at a deficit at that combination
B35: 4. Variable Impact Ranking (Tornado) — Total Budget
B36: Each variable is flexed individually from low to high while holding everything else at base case, to rank which assumptions carry the most budget risk.
B37: Variable | C37: Low case | D37: High case | E37: Total Budget @ Low | F37: Total Budget @ High | G37: Swing ($)
B38: Personnel rate (±10%) | C38: -10% | D38: +10% | E38: =(Assumptions!$C$10*0.9)*(Assumptions!$C$9*Assumptions!$C$6)+(Assumptions!$C$12*0.9)*(Assumptions!$C$11*Assumptions!$C$6)+'Budget Model'!$E$14+'Budget Model'!$E$19+'Budget Model'!$E$24+(ROUNDUP((Assumptions!$C$40)/Assumptions!$C$48,0)*Assumptions!$C$34*Assumptions!$C$35)*Assumptions!$C$32+(ROUNDUP((Assumptions!$C$40)/Assumptions!$C$48,0)*Assumptions!$C$34*(1-Assumptions!$C$35))*Assumptions!$C$33 -> 36640.8 | F38: =(Assumptions!$C$10*1.1)*(Assumptions!$C$9*Assumptions!$C$6)+(Assumptions!$C$12*1.1)*(Assumptions!$C$11*Assumptions!$C$6)+'Budget Model'!$E$14+'Budget Model'!$E$19+'Budget Model'!$E$24+(ROUNDUP((Assumptions!$C$40)/Assumptions!$C$48,0)*Assumptions!$C$34*Assumptions!$C$35)*Assumptions!$C$32+(ROUNDUP((Assumptions!$C$40)/Assumptions!$C$48,0)*Assumptions!$C$34*(1-Assumptions!$C$35))*Assumptions!$C$33 -> 44252.8 | G38: =ABS(F38-E38) -> 7612
B39: Course enrollment (50%–150%) | C39: -50% | D39: +50% | E39: ='Budget Model'!$E$9+'Budget Model'!$E$14+'Budget Model'!$E$19+'Budget Model'!$E$24+((ROUNDUP(((Assumptions!$C$40*0.5))/Assumptions!$C$48,0)*Assumptions!$C$34*Assumptions!$C$35)*Assumptions!$C$32+(ROUNDUP(((Assumptions!$C$40*0.5))/Assumptions!$C$48,0)*Assumptions!$C$34*(1-Assumptions!$C$35))*Assumptions!$C$33) -> 40378.4 | F39: ='Budget Model'!$E$9+'Budget Model'!$E$14+'Budget Model'!$E$19+'Budget Model'!$E$24+((ROUNDUP(((Assumptions!$C$40*1.5))/Assumptions!$C$48,0)*Assumptions!$C$34*Assumptions!$C$35)*Assumptions!$C$32+(ROUNDUP(((Assumptions!$C$40*1.5))/Assumptions!$C$48,0)*Assumptions!$C$34*(1-Assumptions!$C$35))*Assumptions!$C$33) -> 40515.2 | G39: =ABS(F39-E39) -> 136.8
B40: Assessor hrs/batch (1.0–2.5) | C40: 1.0 hr | D40: 2.5 hrs | E40: ='Budget Model'!$E$9+'Budget Model'!$E$14+'Budget Model'!$E$19+'Budget Model'!$E$24+((ROUNDUP((Assumptions!$C$40)/Assumptions!$C$48,0)*1*Assumptions!$C$35)*Assumptions!$C$32+(ROUNDUP((Assumptions!$C$40)/Assumptions!$C$48,0)*1*(1-Assumptions!$C$35))*Assumptions!$C$33) -> 40401.2 | F40: ='Budget Model'!$E$9+'Budget Model'!$E$14+'Budget Model'!$E$19+'Budget Model'!$E$24+((ROUNDUP((Assumptions!$C$40)/Assumptions!$C$48,0)*2.5*Assumptions!$C$35)*Assumptions!$C$32+(ROUNDUP((Assumptions!$C$40)/Assumptions!$C$48,0)*2.5*(1-Assumptions!$C$35))*Assumptions!$C$33) -> 40538 | G40: =ABS(F40-E40) -> 136.8
B41: Open Call outcomes (sessions awarded) | C41: 3 wbnr / 1 wksp | D41: 5 wbnr / 2 wksp | E41: ='Budget Model'!$E$9+'Budget Model'!$E$14+'Budget Model'!$E$19+'Budget Model'!$E$29+((Assumptions!$C$27*3)+(Assumptions!$C$29*1)) -> 40446.8 | F41: ='Budget Model'!$E$9+'Budget Model'!$E$14+'Budget Model'!$E$19+'Budget Model'!$E$29+((Assumptions!$C$27*5)+(Assumptions!$C$29*2)) -> 41046.8 | G41: =ABS(F41-E41) -> 600
B43: Sorted by analyst read: personnel rate and Open-Call outcomes carry the largest swing; see Dashboard for the chart.

Sheet ROI & Breakeven
B2: ROI & Break-Even Analysis
B3: How many enrollments are needed for ROI = 0, using the Low/High Open Call cases from the tornado ranking
B5: Methodology: fixed costs (personnel, platform, communications, presenter honoraria) are held constant within each scenario. The only cost that varies with enrollment is student assessor time, and it applies to evergreen courses only. Course revenue is stated net of assessor cost (contribution margin). Two Open Call outcomes are tested — Low = 3 webinars / 1 workshop, High = 5 webinars / 2 workshops — both holding 2 evergreen courses.
C7: Low Case | D7: High Case
B8: 1. Scenario Definition
B9: Webinars awarded | C9: =Assumptions!$C$52 -> 3 | D9: =Assumptions!$C$54 -> 5
B10: Workshops awarded | C10: =Assumptions!$C$53 -> 1 | D10: =Assumptions!$C$55 -> 2
B11: Evergreen courses | C11: =Assumptions!$C$51 -> 2 | D11: =Assumptions!$C$51 -> 2
B13: 2. Fixed Cost Build (excl. assessor honoraria)
B14: Personnel | C14: ='Budget Model'!$E$9 -> 38060 | D14: ='Budget Model'!$E$9 -> 38060
B15: Platform & hosting | C15: ='Budget Model'!$E$14 -> 1200 | D15: ='Budget Model'!$E$14 -> 1200
B16: Communications (scales w/ sessions) | C16: =Assumptions!$C$22*(C9+C10) -> 240 | D16: =Assumptions!$C$22*(D9+D10) -> 420
B17: Presenter honoraria | C17: =Assumptions!$C$27*C9+Assumptions!$C$29*C10 -> 750 | D17: =Assumptions!$C$27*D9+Assumptions!$C$29*D10 -> 1350
B18: Fixed Cost Subtotal | C18: =SUM(C14:C17) -> 40250 | D18: =SUM(D14:D17) -> 41030
B20: 3. Contribution Margin per Enrollment
B21: Webinar price | C21: =Assumptions!$C$43 -> 45 | D21: =Assumptions!$C$43 -> 45
B22: Workshop price | C22: =Assumptions!$C$44 -> 85 | D22: =Assumptions!$C$44 -> 85
B23: Evergreen course price | C23: =Assumptions!$C$45 -> 150 | D23: =Assumptions!$C$45 -> 150
B24: Less: assessor cost per course enrollment | C24: =(Assumptions!$C$34/Assumptions!$C$48)*(Assumptions!$C$35*Assumptions!$C$32+(1-Assumptions!$C$35)*Assumptions!$C$33) -> 3.42 | D24: =(Assumptions!$C$34/Assumptions!$C$48)*(Assumptions!$C$35*Assumptions!$C$32+(1-Assumptions!$C$35)*Assumptions!$C$33) -> 3.42
B25: Course contribution margin (net) | C25: =C23-C24 -> 146.58 | D25: =D23-D24 -> 146.58
B27: Assessor cost is treated as a smooth per-enrollment rate here to solve algebraically for the break-even point; the verification rows below re-check the result using the real batch-rounded (step) cost from the Budget Model.
B29: 4. Base-Case Reference (current average enrollment)
B30: Avg. registrations / webinar (current) | C30: =Assumptions!$C$38 -> 12 | D30: =Assumptions!$C$38 -> 12
B31: Avg. registrations / workshop (current) | C31: =Assumptions!$C$39 -> 15 | D31: =Assumptions!$C$39 -> 15
B32: Evergreen course enrollment (current) | C32: =Assumptions!$C$40 -> 40 | D32: =Assumptions!$C$40 -> 40
B33: → Base webinar revenue | C33: =C21*C30*C9 -> 1620 | D33: =D21*D30*D9 -> 2700
B34: → Base workshop revenue | C34: =C22*C31*C10 -> 1275 | D34: =D22*D31*D10 -> 2550
B35: → Base course revenue (net of actual assessor cost) | C35: =C23*C32-((ROUNDUP((C32)/Assumptions!$C$48,0)*Assumptions!$C$34*Assumptions!$C$35)*Assumptions!$C$32+(ROUNDUP((C32)/Assumptions!$C$48,0)*Assumptions!$C$34*(1-Assumptions!$C$35))*Assumptions!$C$33) -> 5863.2 | D35: =D23*D32-((ROUNDUP((D32)/Assumptions!$C$48,0)*Assumptions!$C$34*Assumptions!$C$35)*Assumptions!$C$32+(ROUNDUP((D32)/Assumptions!$C$48,0)*Assumptions!$C$34*(1-Assumptions!$C$35))*Assumptions!$C$33) -> 5863.2
B36: Base Total Revenue | C36: =C33+C34+C35 -> 8758.2 | D36: =D33+D34+D35 -> 11113.2
B37: BASE-CASE NET POSITION (current avg. enrollment) | C37: =C36-C18 -> -31491.8 | D37: =D36-D18 -> -29916.8
B39: 5. Break-Even Enrollment Required (ROI = 0), Holding Other Channels at Base Case
B40: Required avg. registrations / webinar | C40: =(C18-(C34+C35))/(C21*C9) -> 245.27259 | D40: =(D18-(D34+D35))/(D21*D9) -> 144.96356
B41: → Multiple of current webinar avg. | C41: =C40/C30 -> 20.439383 | D41: =D40/D30 -> 12.080296
B42: Required avg. registrations / workshop | C42: =(C18-(C33+C35))/(C22*C10) -> 385.49176 | D42: =(D18-(D33+D35))/(D22*D10) -> 190.98118
B43: → Multiple of current workshop avg. | C43: =C42/C31 -> 25.699451 | D43: =D42/D31 -> 12.732078
B44: Required evergreen course enrollment | C44: =(C18-(C33+C34))/C25 -> 254.84377 | D44: =(D18-(D33+D34))/D25 -> 244.09879
B45: → Multiple of current course enrollment | C45: =C44/C32 -> 6.3710943 | D45: =D44/D32 -> 6.1024696
B47: Verification (rounded to nearest batch of 10, real stepped assessor cost applied): confirms the algebraic course break-even holds once the batch-rounding rule is reapplied.
B48: Required course enrollment, rounded up to nearest 10 | C48: =CEILING(C44,10) -> 260 | D48: =CEILING(D44,10) -> 250
B49: → Net position check at rounded enrollment (should be ≥ $0) | C49: =(C33+C34+C23*C48-((ROUNDUP((C48)/Assumptions!$C$48,0)*Assumptions!$C$34*Assumptions!$C$35)*Assumptions!$C$32+(ROUNDUP((C48)/Assumptions!$C$48,0)*Assumptions!$C$34*(1-Assumptions!$C$35))*Assumptions!$C$33))-C18 -> 755.8 | D49: =(D33+D34+D23*D48-((ROUNDUP((D48)/Assumptions!$C$48,0)*Assumptions!$C$34*Assumptions!$C$35)*Assumptions!$C$32+(ROUNDUP((D48)/Assumptions!$C$48,0)*Assumptions!$C$34*(1-Assumptions!$C$35))*Assumptions!$C$33))-D18 -> 865
...

Sheet Prudent Scenario
B2: Prudent Scenario — Right-Sized Staffing & Phased Rollout
B3: A more measured operating model: reduced Instructional Technologist / Program Supervisor hours, evergreen courses run as repeatable cohorts, and continuation webinars from pilot topics
B5: Storytelling premise: the Instructional Technologist role was budgeted at full-time (35 hrs/wk), but current program scope doesn't sustain that utilization. This scenario right-sizes both staff roles and replaces a single large course intake with 2–3 smaller, repeatable cohorts in the final 13 weeks, plus 2–3 continuation webinars drawn from pilot-tested topics which is a more regular, sustainable cadence instead of one-off spikes.
C7: Conservative | D7: Stretch
B8: 1. Scenario Definition
B9: Program Supervisor hrs/week | C9: =Assumptions!$C$58 -> 15 | D9: =Assumptions!$C$58 -> 15
B10: Instructional Technologist hrs/week | C10: =Assumptions!$C$59 -> 20 | D10: =Assumptions!$C$59 -> 20
B11: Base webinars (confirmed plan) | C11: =Assumptions!$C$52 -> 3 | D11: =Assumptions!$C$52 -> 3
B12: + Continuation webinars (pilot topics) | C12: =Assumptions!$C$61 -> 2 | D12: =Assumptions!$C$62 -> 3
B13: Total webinars | C13: =C11+C12 -> 5 | D13: =D11+D12 -> 6
B14: Workshops (unchanged) | C14: =Assumptions!$C$53 -> 1 | D14: =Assumptions!$C$53 -> 1
B15: Evergreen courses | C15: =Assumptions!$C$51 -> 2 | D15: =Assumptions!$C$51 -> 2
B16: Cohorts per course (final 13 weeks) | C16: =Assumptions!$C$63 -> 2 | D16: =Assumptions!$C$64 -> 3
B17: Enrollment per cohort, per course | C17: =Assumptions!$C$65 -> 20 | D17: =Assumptions!$C$65 -> 20
B18: Total evergreen course enrollment | C18: =C15*C16*C17 -> 80 | D18: =D15*D16*D17 -> 120
B20: 2. Fixed Cost Build (right-sized personnel)
B21: Program Supervisor | C21: =Assumptions!$C$10*C9*Assumptions!$C$6 -> 13200 | D21: =Assumptions!$C$10*D9*Assumptions!$C$6 -> 13200
B22: Instructional Technologist | C22: =Assumptions!$C$12*C10*Assumptions!$C$6 -> 13200 | D22: =Assumptions!$C$12*D10*Assumptions!$C$6 -> 13200
B23: Personnel Subtotal | C23: =C21+C22 -> 26400 | D23: =D21+D22 -> 26400
B24: Platform & hosting | C24: =Assumptions!$C$16*Assumptions!$C$17+Assumptions!$C$18 -> 1200 | D24: =Assumptions!$C$16*Assumptions!$C$17+Assumptions!$C$18 -> 1200
B25: Communications (webinars + workshops + cohort intakes) | C25: =Assumptions!$C$22*(C13+C14+C16) -> 480 | D25: =Assumptions!$C$22*(D13+D14+D16) -> 600
B26: Presenter honoraria | C26: =Assumptions!$C$27*C13+Assumptions!$C$29*C14 -> 1050 | D26: =Assumptions!$C$27*D13+Assumptions!$C$29*D14 -> 1200
B27: Fixed Cost Subtotal | C27: =C23+C24+C25+C26 -> 29130 | D27: =D23+D24+D25+D26 -> 29400
B29: 3. Assessor Honoraria (batch-based, per cohort per course)
B30: Batches per cohort | C30: =ROUNDUP((C17)/Assumptions!$C$48,0) -> 2 | D30: =ROUNDUP((D17)/Assumptions!$C$48,0) -> 2
B31: Total batches (courses × cohorts × batches/cohort) | C31: =C15*C16*C30 -> 8 | D31: =D15*D16*D30 -> 12
B32: Total assessor hours | C32: =C31*Assumptions!$C$34 -> 12 | D32: =D31*Assumptions!$C$34 -> 18
B33: Assessor Honoraria Cost | C33: =C32*Assumptions!$C$35*Assumptions!$C$32+C32*(1-Assumptions!$C$35)*Assumptions!$C$33 -> 273.6 | D33: =D32*Assumptions!$C$35*Assumptions!$C$32+D32*(1-Assumptions!$C$35)*Assumptions!$C$33 -> 410.4
B35: 4. Revenue & Net Position
B36: Webinar revenue | C36: =Assumptions!$C$43*Assumptions!$C$38*C13 -> 2700 | D36: =Assumptions!$C$43*Assumptions!$C$38*D13 -> 3240
B37: Workshop revenue | C37: =Assumptions!$C$44*Assumptions!$C$39*C14 -> 1275 | D37: =Assumptions!$C$44*Assumptions!$C$39*D14 -> 1275
B38: Evergreen course revenue (gross) | C38: =Assumptions!$C$45*C18 -> 12000 | D38: =Assumptions!$C$45*D18 -> 18000
B39: Total Revenue | C39: =C36+C37+C38 -> 15975 | D39: =D36+D37+D38 -> 22515
B40: Total Cost (Fixed + Assessor) | C40: =C27+C33 -> 29403.6 | D40: =D27+D33 -> 29810.4
B41: NET POSITION | C41: =C39-C40 -> -13428.6 | D41: =D39-D40 -> -7295.4
B43: 5. Blended Break-Even Multiple (uniform growth)
B44: Assessor marginal cost per course enrollment | C44: =(Assumptions!$C$34/Assumptions!$C$48)*(Assumptions!$C$35*Assumptions!$C$32+(1-Assumptions!$C$35)*Assumptions!$C$33) -> 3.42 | D44: =(Assumptions!$C$34/Assumptions!$C$48)*(Assumptions!$C$35*Assumptions!$C$32+(1-Assumptions!$C$35)*Assumptions!$C$33) -> 3.42
B45: Required uniform growth multiplier (x current) | C45: =C27/(C39-C44*C18) -> 1.8552486 | D45: =D27/(D39-D44*D18) -> 1.3300399
B48: 6. Comparison — Original Staffing vs. Prudent Scenario
C49: Original (Low Case) | D49: Prudent — Conservative | E49: Prudent — Stretch
...

Sheet Dashboard
B2: Dashboard
B3: Cost composition, scenario range, and the variables that matter most
B6: Cost Composition — Base Case
B7: Category | C7: Amount
B8: Personnel | C8: ='Budget Model'!$E$9 -> 38060
B9: Platform & Hosting | C9: ='Budget Model'!$E$14 -> 1200
B10: Communications | C10: ='Budget Model'!$E$19 -> 300
B11: Presenter Honoraria | C11: ='Budget Model'!$E$24 -> 750
B12: Assessor Honoraria | C12: ='Budget Model'!$E$29 -> 136.8
B14: Net Position by Scenario (Current Pricing column)
B15: Enrollment Scenario | C15: Net Position
B16: Low | C16: ='Sensitivity Analysis'!$D$29 -> -35930.9
B17: Base | C17: ='Sensitivity Analysis'!$D$30 -> -31551.8
B18: High | C18: ='Sensitivity Analysis'!$D$31 -> -27172.7
B21: Variable Impact Ranking (Tornado)
B22: Variable | C22: Low | D22: High
B23: ='Sensitivity Analysis'!$B$38 -> Personnel rate (±10%) | C23: ='Sensitivity Analysis'!$E$38 -> 36640.8 | D23: ='Sensitivity Analysis'!$F$38 -> 44252.8
B24: ='Sensitivity Analysis'!$B$39 -> Course enrollment (50%–150%) | C24: ='Sensitivity Analysis'!$E$39 -> 40378.4 | D24: ='Sensitivity Analysis'!$F$39 -> 40515.2
B25: ='Sensitivity Analysis'!$B$40 -> Assessor hrs/batch (1.0–2.5) | C25: ='Sensitivity Analysis'!$E$40 -> 40401.2 | D25: ='Sensitivity Analysis'!$F$40 -> 40538
B26: ='Sensitivity Analysis'!$B$41 -> Open Call outcomes (sessions awarded) | C26: ='Sensitivity Analysis'!$E$41 -> 40446.8 | D26: ='Sensitivity Analysis'!$F$41 -> 41046.8
B28: Read: bars show the Total Budget at each variable's low and high case. Wider gaps = bigger planning risk; personnel rate and Open Call outcomes dominate.
